initialize
train
wandb: Currently logged in as: dplars (use `wandb login --relogin` to force relogin)
wandb: WARNING Ignored wandb.init() arg project when running a sweep
PyTorch Version:  1.7.0
Torchvision Version:  0.8.1
   bn  pn  bullet           foldername             imgname   value
0   1   1     0.0  batch_001_plate_001  b_001_p_001_nb.jpg  50.730
1   1   1     1.0  batch_001_plate_001   b_001_p_001_b.jpg  57.122
2   1   2     0.0  batch_001_plate_002  b_001_p_002_nb.jpg  46.985
3   1   2     1.0  batch_001_plate_002   b_001_p_002_b.jpg  68.904
4   1   3     1.0  batch_001_plate_003   b_001_p_003_b.jpg  35.349
/Users/larsdepauw/Documents/Lars.nosync/Documents/School/1Ma ing/Masterproef/TWI/code/Vision/wandb/TSU_AllNetworks_4_spaghetti/TestCameraSetup/data/spaghetti_dataset_sorted/white/train/bad/
(480, 640, 3)
(480, 640, 3)
(480, 640, 3)
(480, 640, 3)
(480, 640, 3)
/Users/larsdepauw/Documents/Lars.nosync/Documents/School/1Ma ing/Masterproef/TWI/code/Vision/wandb/TSU_AllNetworks_4_spaghetti/TestCameraSetup/data/spaghetti_dataset_sorted/red/train/bad/
(480, 640, 3)
(480, 640, 3)
(480, 640, 3)
(480, 640, 3)
(480, 640, 3)
wandb: Currently logged in as: dplars (use `wandb login --relogin` to force relogin)
wandb: WARNING Ignored wandb.init() arg project when running a sweep
PyTorch Version:  1.7.0
Torchvision Version:  0.8.1
   bn  pn  bullet           foldername             imgname   value
0   1   1     0.0  batch_001_plate_001  b_001_p_001_nb.jpg  50.730
1   1   1     1.0  batch_001_plate_001   b_001_p_001_b.jpg  57.122
2   1   2     0.0  batch_001_plate_002  b_001_p_002_nb.jpg  46.985
3   1   2     1.0  batch_001_plate_002   b_001_p_002_b.jpg  68.904
4   1   3     1.0  batch_001_plate_003   b_001_p_003_b.jpg  35.349
/Users/larsdepauw/Documents/Lars.nosync/Documents/School/1Ma ing/Masterproef/TWI/code/Vision/wandb/TSU_AllNetworks_4_spaghetti/TestCameraSetup/data/spaghetti_dataset_sorted/white/train/bad/
(480, 640, 3)
(480, 640, 3)
(480, 640, 3)
(480, 640, 3)
(480, 640, 3)
/Users/larsdepauw/Documents/Lars.nosync/Documents/School/1Ma ing/Masterproef/TWI/code/Vision/wandb/TSU_AllNetworks_4_spaghetti/TestCameraSetup/data/spaghetti_dataset_sorted/red/train/bad/
(480, 640, 3)
(480, 640, 3)
(480, 640, 3)
(480, 640, 3)
(480, 640, 3)
Traceback (most recent call last):
  File "/Users/larsdepauw/anaconda3/lib/python3.8/site-packages/wandb/sdk/wandb_init.py", line 575, in init
    run = wi.init()
  File "/Users/larsdepauw/anaconda3/lib/python3.8/site-packages/wandb/sdk/wandb_init.py", line 367, in init
    backend.ensure_launched(
  File "/Users/larsdepauw/anaconda3/lib/python3.8/site-packages/wandb/sdk/backend/backend.py", line 81, in ensure_launched
    self.wandb_process.start()
  File "/Users/larsdepauw/anaconda3/lib/python3.8/multiprocessing/process.py", line 121, in start
    self._popen = self._Popen(self)
  File "/Users/larsdepauw/anaconda3/lib/python3.8/multiprocessing/context.py", line 284, in _Popen
    return Popen(process_obj)
  File "/Users/larsdepauw/anaconda3/lib/python3.8/multiprocessing/popen_spawn_posix.py", line 32, in __init__
    super().__init__(process_obj)
  File "/Users/larsdepauw/anaconda3/lib/python3.8/multiprocessing/popen_fork.py", line 19, in __init__
    self._launch(process_obj)
  File "/Users/larsdepauw/anaconda3/lib/python3.8/multiprocessing/popen_spawn_posix.py", line 42, in _launch
    prep_data = spawn.get_preparation_data(process_obj._name)
  File "/Users/larsdepauw/anaconda3/lib/python3.8/multiprocessing/spawn.py", line 154, in get_preparation_data
    _check_not_importing_main()
  File "/Users/larsdepauw/anaconda3/lib/python3.8/multiprocessing/spawn.py", line 134, in _check_not_importing_main
    raise RuntimeError('''
RuntimeError: 
        An attempt has been made to start a new process before the
        current process has finished its bootstrapping phase.

        This probably means that you are not using fork to start your
        child processes and you have forgotten to use the proper idiom
        in the main module:

            if __name__ == '__main__':
                freeze_support()
                ...

        The "freeze_support()" line can be omitted if the program
        is not going to be frozen to produce an executable.
wandb: ERROR Abnormal program exit
Traceback (most recent call last):
  File "/Users/larsdepauw/anaconda3/lib/python3.8/site-packages/wandb/sdk/wandb_init.py", line 575, in init
    run = wi.init()
  File "/Users/larsdepauw/anaconda3/lib/python3.8/site-packages/wandb/sdk/wandb_init.py", line 367, in init
    backend.ensure_launched(
  File "/Users/larsdepauw/anaconda3/lib/python3.8/site-packages/wandb/sdk/backend/backend.py", line 81, in ensure_launched
    self.wandb_process.start()
  File "/Users/larsdepauw/anaconda3/lib/python3.8/multiprocessing/process.py", line 121, in start
    self._popen = self._Popen(self)
  File "/Users/larsdepauw/anaconda3/lib/python3.8/multiprocessing/context.py", line 284, in _Popen
    return Popen(process_obj)
  File "/Users/larsdepauw/anaconda3/lib/python3.8/multiprocessing/popen_spawn_posix.py", line 32, in __init__
    super().__init__(process_obj)
  File "/Users/larsdepauw/anaconda3/lib/python3.8/multiprocessing/popen_fork.py", line 19, in __init__
    self._launch(process_obj)
  File "/Users/larsdepauw/anaconda3/lib/python3.8/multiprocessing/popen_spawn_posix.py", line 42, in _launch
    prep_data = spawn.get_preparation_data(process_obj._name)
  File "/Users/larsdepauw/anaconda3/lib/python3.8/multiprocessing/spawn.py", line 154, in get_preparation_data
    _check_not_importing_main()
  File "/Users/larsdepauw/anaconda3/lib/python3.8/multiprocessing/spawn.py", line 134, in _check_not_importing_main
    raise RuntimeError('''
RuntimeError: 
        An attempt has been made to start a new process before the
        current process has finished its bootstrapping phase.

        This probably means that you are not using fork to start your
        child processes and you have forgotten to use the proper idiom
        in the main module:

            if __name__ == '__main__':
                freeze_support()
                ...

        The "freeze_support()" line can be omitted if the program
        is not going to be frozen to produce an executable.

The above exception was the direct cause of the following exception:

Traceback (most recent call last):
  File "<string>", line 1, in <module>
  File "/Users/larsdepauw/anaconda3/lib/python3.8/multiprocessing/spawn.py", line 116, in spawn_main
    exitcode = _main(fd, parent_sentinel)
  File "/Users/larsdepauw/anaconda3/lib/python3.8/multiprocessing/spawn.py", line 125, in _main
    prepare(preparation_data)
  File "/Users/larsdepauw/anaconda3/lib/python3.8/multiprocessing/spawn.py", line 236, in prepare
    _fixup_main_from_path(data['init_main_from_path'])
  File "/Users/larsdepauw/anaconda3/lib/python3.8/multiprocessing/spawn.py", line 287, in _fixup_main_from_path
    main_content = runpy.run_path(main_path,
  File "/Users/larsdepauw/anaconda3/lib/python3.8/runpy.py", line 265, in run_path
    return _run_module_code(code, init_globals, run_name,
  File "/Users/larsdepauw/anaconda3/lib/python3.8/runpy.py", line 97, in _run_module_code
    _run_code(code, mod_globals, init_globals,
  File "/Users/larsdepauw/anaconda3/lib/python3.8/runpy.py", line 87, in _run_code
    exec(code, run_globals)
  File "/Users/larsdepauw/Documents/Lars.nosync/Documents/School/1Ma ing/Masterproef/TWI/code/Vision/wandb/TSU_AllNetworks_4_spaghetti/TestCameraSetup/AllNetworks/train.py", line 668, in <module>
    wandb.init(config=default_config, project="pytorch-TWI_spaghetti_sweep")
  File "/Users/larsdepauw/anaconda3/lib/python3.8/site-packages/wandb/sdk/wandb_init.py", line 612, in init
    six.raise_from(Exception("problem"), error_seen)
  File "<string>", line 3, in raise_from
Exception: problem
Problem at: /Users/larsdepauw/Documents/Lars.nosync/Documents/School/1Ma ing/Masterproef/TWI/code/Vision/wandb/TSU_AllNetworks_4_spaghetti/TestCameraSetup/AllNetworks/train.py 668 <module>
Traceback (most recent call last):
  File "/Users/larsdepauw/anaconda3/lib/python3.8/site-packages/wandb/sdk/wandb_init.py", line 575, in init
    run = wi.init()
  File "/Users/larsdepauw/anaconda3/lib/python3.8/site-packages/wandb/sdk/wandb_init.py", line 367, in init
    backend.ensure_launched(
  File "/Users/larsdepauw/anaconda3/lib/python3.8/site-packages/wandb/sdk/backend/backend.py", line 81, in ensure_launched
    self.wandb_process.start()
  File "/Users/larsdepauw/anaconda3/lib/python3.8/multiprocessing/process.py", line 121, in start
    self._popen = self._Popen(self)
  File "/Users/larsdepauw/anaconda3/lib/python3.8/multiprocessing/context.py", line 284, in _Popen
    return Popen(process_obj)
  File "/Users/larsdepauw/anaconda3/lib/python3.8/multiprocessing/popen_spawn_posix.py", line 32, in __init__
    super().__init__(process_obj)
  File "/Users/larsdepauw/anaconda3/lib/python3.8/multiprocessing/popen_fork.py", line 19, in __init__
    self._launch(process_obj)
  File "/Users/larsdepauw/anaconda3/lib/python3.8/multiprocessing/popen_spawn_posix.py", line 42, in _launch
    prep_data = spawn.get_preparation_data(process_obj._name)
  File "/Users/larsdepauw/anaconda3/lib/python3.8/multiprocessing/spawn.py", line 154, in get_preparation_data
    _check_not_importing_main()
  File "/Users/larsdepauw/anaconda3/lib/python3.8/multiprocessing/spawn.py", line 134, in _check_not_importing_main
    raise RuntimeError('''
RuntimeError: 
        An attempt has been made to start a new process before the
        current process has finished its bootstrapping phase.

        This probably means that you are not using fork to start your
        child processes and you have forgotten to use the proper idiom
        in the main module:

            if __name__ == '__main__':
                freeze_support()
                ...

        The "freeze_support()" line can be omitted if the program
        is not going to be frozen to produce an executable.
wandb: ERROR Abnormal program exit
Traceback (most recent call last):
  File "/Users/larsdepauw/anaconda3/lib/python3.8/site-packages/wandb/sdk/wandb_init.py", line 575, in init
    run = wi.init()
  File "/Users/larsdepauw/anaconda3/lib/python3.8/site-packages/wandb/sdk/wandb_init.py", line 367, in init
    backend.ensure_launched(
  File "/Users/larsdepauw/anaconda3/lib/python3.8/site-packages/wandb/sdk/backend/backend.py", line 81, in ensure_launched
    self.wandb_process.start()
  File "/Users/larsdepauw/anaconda3/lib/python3.8/multiprocessing/process.py", line 121, in start
    self._popen = self._Popen(self)
  File "/Users/larsdepauw/anaconda3/lib/python3.8/multiprocessing/context.py", line 284, in _Popen
    return Popen(process_obj)
  File "/Users/larsdepauw/anaconda3/lib/python3.8/multiprocessing/popen_spawn_posix.py", line 32, in __init__
    super().__init__(process_obj)
  File "/Users/larsdepauw/anaconda3/lib/python3.8/multiprocessing/popen_fork.py", line 19, in __init__
    self._launch(process_obj)
  File "/Users/larsdepauw/anaconda3/lib/python3.8/multiprocessing/popen_spawn_posix.py", line 42, in _launch
    prep_data = spawn.get_preparation_data(process_obj._name)
  File "/Users/larsdepauw/anaconda3/lib/python3.8/multiprocessing/spawn.py", line 154, in get_preparation_data
    _check_not_importing_main()
  File "/Users/larsdepauw/anaconda3/lib/python3.8/multiprocessing/spawn.py", line 134, in _check_not_importing_main
    raise RuntimeError('''
RuntimeError: 
        An attempt has been made to start a new process before the
        current process has finished its bootstrapping phase.

        This probably means that you are not using fork to start your
        child processes and you have forgotten to use the proper idiom
        in the main module:

            if __name__ == '__main__':
                freeze_support()
                ...

        The "freeze_support()" line can be omitted if the program
        is not going to be frozen to produce an executable.

The above exception was the direct cause of the following exception:

Traceback (most recent call last):
  File "<string>", line 1, in <module>
  File "/Users/larsdepauw/anaconda3/lib/python3.8/multiprocessing/spawn.py", line 116, in spawn_main
    exitcode = _main(fd, parent_sentinel)
  File "/Users/larsdepauw/anaconda3/lib/python3.8/multiprocessing/spawn.py", line 125, in _main
    prepare(preparation_data)
  File "/Users/larsdepauw/anaconda3/lib/python3.8/multiprocessing/spawn.py", line 236, in prepare
    _fixup_main_from_path(data['init_main_from_path'])
  File "/Users/larsdepauw/anaconda3/lib/python3.8/multiprocessing/spawn.py", line 287, in _fixup_main_from_path
    main_content = runpy.run_path(main_path,
  File "/Users/larsdepauw/anaconda3/lib/python3.8/runpy.py", line 265, in run_path
    return _run_module_code(code, init_globals, run_name,
  File "/Users/larsdepauw/anaconda3/lib/python3.8/runpy.py", line 97, in _run_module_code
    _run_code(code, mod_globals, init_globals,
  File "/Users/larsdepauw/anaconda3/lib/python3.8/runpy.py", line 87, in _run_code
    exec(code, run_globals)
  File "/Users/larsdepauw/Documents/Lars.nosync/Documents/School/1Ma ing/Masterproef/TWI/code/Vision/wandb/TSU_AllNetworks_4_spaghetti/TestCameraSetup/AllNetworks/train.py", line 668, in <module>
    wandb.init(config=default_config, project="pytorch-TWI_spaghetti_sweep")
  File "/Users/larsdepauw/anaconda3/lib/python3.8/site-packages/wandb/sdk/wandb_init.py", line 612, in init
    six.raise_from(Exception("problem"), error_seen)
  File "<string>", line 3, in raise_from
Exception: problem
Problem at: /Users/larsdepauw/Documents/Lars.nosync/Documents/School/1Ma ing/Masterproef/TWI/code/Vision/wandb/TSU_AllNetworks_4_spaghetti/TestCameraSetup/AllNetworks/train.py 668 <module>
Traceback (most recent call last):
  File "/Users/larsdepauw/anaconda3/lib/python3.8/site-packages/torch/utils/data/dataloader.py", line 872, in _try_get_data
    data = self._data_queue.get(timeout=timeout)
  File "/Users/larsdepauw/anaconda3/lib/python3.8/multiprocessing/queues.py", line 107, in get
    if not self._poll(timeout):
  File "/Users/larsdepauw/anaconda3/lib/python3.8/multiprocessing/connection.py", line 257, in poll
    return self._poll(timeout)
  File "/Users/larsdepauw/anaconda3/lib/python3.8/multiprocessing/connection.py", line 424, in _poll
    r = wait([self], timeout)
  File "/Users/larsdepauw/anaconda3/lib/python3.8/multiprocessing/connection.py", line 931, in wait
    ready = selector.select(timeout)
  File "/Users/larsdepauw/anaconda3/lib/python3.8/selectors.py", line 415, in select
    fd_event_list = self._selector.poll(timeout)
  File "/Users/larsdepauw/anaconda3/lib/python3.8/site-packages/torch/utils/data/_utils/signal_handling.py", line 66, in handler
    _error_if_any_worker_fails()
RuntimeError: DataLoader worker (pid 21046) exited unexpectedly with exit code 1. Details are lost due to multiprocessing. Rerunning with num_workers=0 may give better error trace.

The above exception was the direct cause of the following exception:

Traceback (most recent call last):
  File "train.py", line 712, in <module>
    run()
  File "train.py", line 690, in run
    _,pt_hist = train_model(pt_model, dataloaders_dict, pt_criterion, pt_optimizer, num_epochs=config.epochs, is_inception=(config.model_name=="inception"))
  File "train.py", line 498, in train_model
    for inputs, labels in dataloaders[phase]:
  File "/Users/larsdepauw/anaconda3/lib/python3.8/site-packages/torch/utils/data/dataloader.py", line 435, in __next__
    data = self._next_data()
  File "/Users/larsdepauw/anaconda3/lib/python3.8/site-packages/torch/utils/data/dataloader.py", line 1068, in _next_data
    idx, data = self._get_data()
  File "/Users/larsdepauw/anaconda3/lib/python3.8/site-packages/torch/utils/data/dataloader.py", line 1034, in _get_data
    success, data = self._try_get_data()
  File "/Users/larsdepauw/anaconda3/lib/python3.8/site-packages/torch/utils/data/dataloader.py", line 885, in _try_get_data
    raise RuntimeError('DataLoader worker (pid(s) {}) exited unexpectedly'.format(pids_str)) from e
RuntimeError: DataLoader worker (pid(s) 21046) exited unexpectedly
